{"primaryContentSections":[{"kind":"declarations","declarations":[{"tokens":[{"kind":"keyword","text":"case"},{"kind":"text","text":" "},{"text":"`internal`","kind":"identifier"},{"text":"(","kind":"text"},{"kind":"typeIdentifier","text":"Error","preciseIdentifier":"s:s5ErrorP"},{"text":"?)","kind":"text"}],"platforms":["iOS"],"languages":["swift"]}]}],"schemaVersion":{"patch":0,"major":0,"minor":3},"sections":[],"hierarchy":{"paths":[["doc:\/\/com.TransmitSecurity.TSAuthenticationSDK\/documentation\/TSAuthenticationSDK","doc:\/\/com.TransmitSecurity.TSAuthenticationSDK\/documentation\/TSAuthenticationSDK\/TSAuthenticationError"]]},"kind":"symbol","identifier":{"url":"doc:\/\/com.TransmitSecurity.TSAuthenticationSDK\/documentation\/TSAuthenticationSDK\/TSAuthenticationError\/internal(_:)","interfaceLanguage":"swift"},"abstract":[{"type":"text","text":"The authorization attempt failed for an unknown reason."}],"metadata":{"symbolKind":"case","roleHeading":"Case","externalID":"s:19TSAuthenticationSDK0A5ErrorO8internalyACs0C0_pSgcACmF","role":"symbol","fragments":[{"kind":"keyword","text":"case"},{"text":" ","kind":"text"},{"kind":"identifier","text":"`internal`"},{"text":"(","kind":"text"},{"kind":"typeIdentifier","preciseIdentifier":"s:s5ErrorP","text":"Error"},{"kind":"text","text":"?)"}],"modules":[{"name":"TSAuthenticationSDK"}],"title":"TSAuthenticationError.internal(_:)"},"variants":[{"traits":[{"interfaceLanguage":"swift"}],"paths":["\/documentation\/tsauthenticationsdk\/tsauthenticationerror\/internal(_:)"]}],"references":{"doc://com.TransmitSecurity.TSAuthenticationSDK/documentation/TSAuthenticationSDK":{"kind":"symbol","abstract":[],"url":"\/documentation\/tsauthenticationsdk","identifier":"doc:\/\/com.TransmitSecurity.TSAuthenticationSDK\/documentation\/TSAuthenticationSDK","role":"collection","title":"TSAuthenticationSDK","type":"topic"},"doc://com.TransmitSecurity.TSAuthenticationSDK/documentation/TSAuthenticationSDK/TSAuthenticationError/internal(_:)":{"title":"TSAuthenticationError.internal(_:)","role":"symbol","type":"topic","abstract":[{"type":"text","text":"The authorization attempt failed for an unknown reason."}],"url":"\/documentation\/tsauthenticationsdk\/tsauthenticationerror\/internal(_:)","kind":"symbol","fragments":[{"kind":"keyword","text":"case"},{"kind":"text","text":" "},{"text":"`internal`","kind":"identifier"},{"text":"(","kind":"text"},{"preciseIdentifier":"s:s5ErrorP","kind":"typeIdentifier","text":"Error"},{"text":"?)","kind":"text"}],"identifier":"doc:\/\/com.TransmitSecurity.TSAuthenticationSDK\/documentation\/TSAuthenticationSDK\/TSAuthenticationError\/internal(_:)"},"doc://com.TransmitSecurity.TSAuthenticationSDK/documentation/TSAuthenticationSDK/TSAuthenticationError":{"role":"symbol","url":"\/documentation\/tsauthenticationsdk\/tsauthenticationerror","fragments":[{"text":"enum","kind":"keyword"},{"kind":"text","text":" "},{"text":"TSAuthenticationError","kind":"identifier"}],"navigatorTitle":[{"kind":"identifier","text":"TSAuthenticationError"}],"title":"TSAuthenticationError","kind":"symbol","type":"topic","identifier":"doc:\/\/com.TransmitSecurity.TSAuthenticationSDK\/documentation\/TSAuthenticationSDK\/TSAuthenticationError","abstract":[]}}}