{"identifier":{"interfaceLanguage":"swift","url":"doc:\/\/com.TransmitSecurity.TSAuthenticationSDK\/documentation\/TSAuthenticationSDK\/TSAuthenticationError\/internal(_:)"},"kind":"symbol","metadata":{"symbolKind":"case","role":"symbol","modules":[{"name":"TSAuthenticationSDK"}],"externalID":"s:19TSAuthenticationSDK0A5ErrorO8internalyACs0C0_pSgcACmF","fragments":[{"text":"case","kind":"keyword"},{"kind":"text","text":" "},{"kind":"identifier","text":"`internal`"},{"text":"(","kind":"text"},{"preciseIdentifier":"s:s5ErrorP","text":"Error","kind":"typeIdentifier"},{"kind":"text","text":"?)"}],"title":"TSAuthenticationError.internal(_:)","roleHeading":"Case"},"hierarchy":{"paths":[["doc:\/\/com.TransmitSecurity.TSAuthenticationSDK\/documentation\/TSAuthenticationSDK","doc:\/\/com.TransmitSecurity.TSAuthenticationSDK\/documentation\/TSAuthenticationSDK\/TSAuthenticationError"]]},"abstract":[{"type":"text","text":"The authorization attempt failed for an unknown reason."}],"primaryContentSections":[{"declarations":[{"tokens":[{"text":"case","kind":"keyword"},{"kind":"text","text":" "},{"kind":"identifier","text":"`internal`"},{"kind":"text","text":"("},{"text":"Error","kind":"typeIdentifier","preciseIdentifier":"s:s5ErrorP"},{"kind":"text","text":"?)"}],"platforms":["iOS"],"languages":["swift"]}],"kind":"declarations"}],"sections":[],"variants":[{"paths":["\/documentation\/tsauthenticationsdk\/tsauthenticationerror\/internal(_:)"],"traits":[{"interfaceLanguage":"swift"}]}],"schemaVersion":{"patch":0,"minor":3,"major":0},"references":{"doc://com.TransmitSecurity.TSAuthenticationSDK/documentation/TSAuthenticationSDK/TSAuthenticationError":{"url":"\/documentation\/tsauthenticationsdk\/tsauthenticationerror","fragments":[{"text":"enum","kind":"keyword"},{"text":" ","kind":"text"},{"text":"TSAuthenticationError","kind":"identifier"}],"role":"symbol","navigatorTitle":[{"text":"TSAuthenticationError","kind":"identifier"}],"title":"TSAuthenticationError","kind":"symbol","type":"topic","identifier":"doc:\/\/com.TransmitSecurity.TSAuthenticationSDK\/documentation\/TSAuthenticationSDK\/TSAuthenticationError","abstract":[]},"doc://com.TransmitSecurity.TSAuthenticationSDK/documentation/TSAuthenticationSDK":{"abstract":[],"url":"\/documentation\/tsauthenticationsdk","identifier":"doc:\/\/com.TransmitSecurity.TSAuthenticationSDK\/documentation\/TSAuthenticationSDK","title":"TSAuthenticationSDK","kind":"symbol","role":"collection","type":"topic"},"doc://com.TransmitSecurity.TSAuthenticationSDK/documentation/TSAuthenticationSDK/TSAuthenticationError/internal(_:)":{"identifier":"doc:\/\/com.TransmitSecurity.TSAuthenticationSDK\/documentation\/TSAuthenticationSDK\/TSAuthenticationError\/internal(_:)","kind":"symbol","fragments":[{"text":"case","kind":"keyword"},{"kind":"text","text":" "},{"text":"`internal`","kind":"identifier"},{"kind":"text","text":"("},{"text":"Error","kind":"typeIdentifier","preciseIdentifier":"s:s5ErrorP"},{"kind":"text","text":"?)"}],"title":"TSAuthenticationError.internal(_:)","abstract":[{"text":"The authorization attempt failed for an unknown reason.","type":"text"}],"type":"topic","url":"\/documentation\/tsauthenticationsdk\/tsauthenticationerror\/internal(_:)","role":"symbol"}}}