{"sections":[],"hierarchy":{"paths":[["doc:\/\/com.TransmitSecurity.TSAuthenticationSDK\/documentation\/TSAuthenticationSDK","doc:\/\/com.TransmitSecurity.TSAuthenticationSDK\/documentation\/TSAuthenticationSDK\/TSWebAuthnError"]]},"metadata":{"role":"symbol","title":"TSWebAuthnError.internal(_:)","modules":[{"name":"TSAuthenticationSDK"}],"fragments":[{"kind":"keyword","text":"case"},{"kind":"text","text":" "},{"kind":"identifier","text":"`internal`"},{"text":"(","kind":"text"},{"text":"Error","preciseIdentifier":"s:s5ErrorP","kind":"typeIdentifier"},{"kind":"text","text":"?)"}],"externalID":"s:19TSAuthenticationSDK15TSWebAuthnErrorO8internalyACs0E0_pSgcACmF","symbolKind":"case","roleHeading":"Case"},"schemaVersion":{"minor":3,"patch":0,"major":0},"identifier":{"interfaceLanguage":"swift","url":"doc:\/\/com.TransmitSecurity.TSAuthenticationSDK\/documentation\/TSAuthenticationSDK\/TSWebAuthnError\/internal(_:)"},"abstract":[{"text":"The authorization attempt failed for an internal reason.","type":"text"}],"kind":"symbol","primaryContentSections":[{"kind":"declarations","declarations":[{"languages":["swift"],"tokens":[{"kind":"keyword","text":"case"},{"text":" ","kind":"text"},{"text":"`internal`","kind":"identifier"},{"text":"(","kind":"text"},{"kind":"typeIdentifier","preciseIdentifier":"s:s5ErrorP","text":"Error"},{"text":"?)","kind":"text"}],"platforms":["iOS"]}]}],"variants":[{"paths":["\/documentation\/tsauthenticationsdk\/tswebauthnerror\/internal(_:)"],"traits":[{"interfaceLanguage":"swift"}]}],"references":{"doc://com.TransmitSecurity.TSAuthenticationSDK/documentation/TSAuthenticationSDK":{"abstract":[],"title":"TSAuthenticationSDK","type":"topic","role":"collection","identifier":"doc:\/\/com.TransmitSecurity.TSAuthenticationSDK\/documentation\/TSAuthenticationSDK","kind":"symbol","url":"\/documentation\/tsauthenticationsdk"},"doc://com.TransmitSecurity.TSAuthenticationSDK/documentation/TSAuthenticationSDK/TSWebAuthnError":{"abstract":[],"url":"\/documentation\/tsauthenticationsdk\/tswebauthnerror","kind":"symbol","fragments":[{"text":"enum","kind":"keyword"},{"kind":"text","text":" "},{"kind":"identifier","text":"TSWebAuthnError"}],"navigatorTitle":[{"kind":"identifier","text":"TSWebAuthnError"}],"identifier":"doc:\/\/com.TransmitSecurity.TSAuthenticationSDK\/documentation\/TSAuthenticationSDK\/TSWebAuthnError","type":"topic","title":"TSWebAuthnError","role":"symbol"},"doc://com.TransmitSecurity.TSAuthenticationSDK/documentation/TSAuthenticationSDK/TSWebAuthnError/internal(_:)":{"url":"\/documentation\/tsauthenticationsdk\/tswebauthnerror\/internal(_:)","abstract":[{"type":"text","text":"The authorization attempt failed for an internal reason."}],"identifier":"doc:\/\/com.TransmitSecurity.TSAuthenticationSDK\/documentation\/TSAuthenticationSDK\/TSWebAuthnError\/internal(_:)","kind":"symbol","role":"symbol","title":"TSWebAuthnError.internal(_:)","type":"topic","fragments":[{"text":"case","kind":"keyword"},{"text":" ","kind":"text"},{"kind":"identifier","text":"`internal`"},{"kind":"text","text":"("},{"kind":"typeIdentifier","text":"Error","preciseIdentifier":"s:s5ErrorP"},{"kind":"text","text":"?)"}]}}}