{"metadata":{"externalID":"s:19TSAuthenticationSDK15TSWebAuthnErrorO8internalyACs0E0_pSgcACmF","role":"symbol","fragments":[{"kind":"keyword","text":"case"},{"text":" ","kind":"text"},{"kind":"identifier","text":"`internal`"},{"text":"(","kind":"text"},{"kind":"typeIdentifier","preciseIdentifier":"s:s5ErrorP","text":"Error"},{"text":"?)","kind":"text"}],"title":"TSWebAuthnError.internal(_:)","modules":[{"name":"TSAuthenticationSDK"}],"symbolKind":"case","roleHeading":"Case"},"identifier":{"url":"doc:\/\/com.TransmitSecurity.TSAuthenticationSDK\/documentation\/TSAuthenticationSDK\/TSWebAuthnError\/internal(_:)","interfaceLanguage":"swift"},"sections":[],"abstract":[{"text":"The authorization attempt failed for an internal reason.","type":"text"}],"kind":"symbol","schemaVersion":{"minor":3,"patch":0,"major":0},"hierarchy":{"paths":[["doc:\/\/com.TransmitSecurity.TSAuthenticationSDK\/documentation\/TSAuthenticationSDK","doc:\/\/com.TransmitSecurity.TSAuthenticationSDK\/documentation\/TSAuthenticationSDK\/TSWebAuthnError"]]},"variants":[{"paths":["\/documentation\/tsauthenticationsdk\/tswebauthnerror\/internal(_:)"],"traits":[{"interfaceLanguage":"swift"}]}],"primaryContentSections":[{"kind":"declarations","declarations":[{"languages":["swift"],"tokens":[{"text":"case","kind":"keyword"},{"text":" ","kind":"text"},{"text":"`internal`","kind":"identifier"},{"text":"(","kind":"text"},{"text":"Error","kind":"typeIdentifier","preciseIdentifier":"s:s5ErrorP"},{"text":"?)","kind":"text"}],"platforms":["iOS"]}]}],"references":{"doc://com.TransmitSecurity.TSAuthenticationSDK/documentation/TSAuthenticationSDK/TSWebAuthnError":{"title":"TSWebAuthnError","identifier":"doc:\/\/com.TransmitSecurity.TSAuthenticationSDK\/documentation\/TSAuthenticationSDK\/TSWebAuthnError","abstract":[],"role":"symbol","fragments":[{"kind":"keyword","text":"enum"},{"text":" ","kind":"text"},{"kind":"identifier","text":"TSWebAuthnError"}],"url":"\/documentation\/tsauthenticationsdk\/tswebauthnerror","navigatorTitle":[{"text":"TSWebAuthnError","kind":"identifier"}],"type":"topic","kind":"symbol"},"doc://com.TransmitSecurity.TSAuthenticationSDK/documentation/TSAuthenticationSDK":{"abstract":[],"url":"\/documentation\/tsauthenticationsdk","kind":"symbol","title":"TSAuthenticationSDK","identifier":"doc:\/\/com.TransmitSecurity.TSAuthenticationSDK\/documentation\/TSAuthenticationSDK","type":"topic","role":"collection"},"doc://com.TransmitSecurity.TSAuthenticationSDK/documentation/TSAuthenticationSDK/TSWebAuthnError/internal(_:)":{"kind":"symbol","fragments":[{"kind":"keyword","text":"case"},{"text":" ","kind":"text"},{"kind":"identifier","text":"`internal`"},{"text":"(","kind":"text"},{"kind":"typeIdentifier","text":"Error","preciseIdentifier":"s:s5ErrorP"},{"kind":"text","text":"?)"}],"type":"topic","url":"\/documentation\/tsauthenticationsdk\/tswebauthnerror\/internal(_:)","identifier":"doc:\/\/com.TransmitSecurity.TSAuthenticationSDK\/documentation\/TSAuthenticationSDK\/TSWebAuthnError\/internal(_:)","title":"TSWebAuthnError.internal(_:)","abstract":[{"type":"text","text":"The authorization attempt failed for an internal reason."}],"role":"symbol"}}}